Workbook

Sheet 汇总
A1: 本地库字段命名风格统计（schema = as_agent）
A2: 口径：实查 information_schema.columns；「下划线列」= 列名含 _ ；「多词连写列」= 列名不含 _ 且长度 ≥ 9（原驼峰被 openGauss 折叠为全小写）。所有指标均由「表清单」sheet 实时汇总。
A3: 命名风格 | B3: 表数量 | C3: 其中备份表 | D3: 业务表数量 | E3: 总列数 | F3: 下划线列 | G3: 多词连写列 | H3: 说明
A4: A 纯下划线 | B4: =COUNTIF(表清单!$C$2:$C$294,$A4) -> 53 | C4: =COUNTIFS(表清单!$C$2:$C$294,$A4,表清单!$D$2:$D$294,"备份表") -> 3 | D4: =B4-C4 -> 50 | E4: =SUMIF(表清单!$C$2:$C$294,$A4,表清单!$E$2:$E$294) -> 582 | F4: =SUMIF(表清单!$C$2:$C$294,$A4,表清单!$F$2:$F$294) -> 488 | G4: =SUMIF(表清单!$C$2:$C$294,$A4,表清单!$G$2:$G$294) -> 0 | H4: 多词字段一律下划线分隔，符合主流规范
A5: B 混用 | B5: =COUNTIF(表清单!$C$2:$C$294,$A5) -> 46 | C5: =COUNTIFS(表清单!$C$2:$C$294,$A5,表清单!$D$2:$D$294,"备份表") -> 18 | D5: =B5-C5 -> 28 | E5: =SUMIF(表清单!$C$2:$C$294,$A5,表清单!$E$2:$E$294) -> 922 | F5: =SUMIF(表清单!$C$2:$C$294,$A5,表清单!$F$2:$F$294) -> 427 | G5: =SUMIF(表清单!$C$2:$C$294,$A5,表清单!$G$2:$G$294) -> 274 | H5: 既有下划线列、又有多词连写列，多为多次改表遗留
A6: C 全连写 | B6: =COUNTIF(表清单!$C$2:$C$294,$A6) -> 194 | C6: =COUNTIFS(表清单!$C$2:$C$294,$A6,表清单!$D$2:$D$294,"备份表") -> 104 | D6: =B6-C6 -> 90 | E6: =SUMIF(表清单!$C$2:$C$294,$A6,表清单!$E$2:$E$294) -> 3737 | F6: =SUMIF(表清单!$C$2:$C$294,$A6,表清单!$F$2:$F$294) -> 0 | G6: =SUMIF(表清单!$C$2:$C$294,$A6,表清单!$G$2:$G$294) -> 2816 | H6: 原驼峰被折叠成全小写连写（如 reportno），无下划线列
A7: 合计 | B7: =SUM(B4:B6) -> 293 | C7: =SUM(C4:C6) -> 125 | D7: =SUM(D4:D6) -> 168 | E7: =SUM(E4:E6) -> 5241 | F7: =SUM(F4:F6) -> 915 | G7: =SUM(G4:G6) -> 3090 | H7: 293 张表、5241 列（含 125 张 bak 备份表）
A9: 关键结论：
A10: 1. 全库不存在「真·驼峰（列名含大写字母）」的业务表。openGauss 会把未加双引号的标识符折叠为小写，所以驼峰写法落库后一律变成全小写连写（reportno / customername / checktaskno）。
A11: 2. 唯一保留大写字母的列只有 CONDITION，出现在 app_credit_approval_manage_req_info 及其 3 张 bak 表。它是保留字，建表时加了双引号；查/写 SQL 必须写成 "CONDITION"，否则报 column "condition" does not exist。
A12: 3. 纯下划线风格的 53 张表集中在中后台配置类：sys_*、knowledge_*、ext_intf_*、collector_*、rule_*、prompt_* 等。
A13: 4. 全连写 194 张表中有 104 张是 bak_ 备份表；真正的业务表（app_* / xd_* / ws_* / zx_* / dfs_*）基本都走连写风格。
A14: 5. 混用的 46 张表风险最高：同一张表里两套写法并存（如 index_params 有 count_field 也有 publicparamstatus），写 SQL 与做实体映射时最容易踩坑。

Sheet 表清单
A1: 序号 | B1: 表名 | C1: 命名风格 | D1: 表类别 | E1: 总列数 | F1: 下划线列数 | G1: 多词连写列数 | H1: 含大写列数 | I1: 下划线列清单 | J1: 备注
A2: 1 | B2: agent_config | C2: A 纯下划线 | D2: 业务表 | E2: 14 | F2: 13 | G2: 0 | H2: 0 | I2: agent_name,agent_code,entity_type,agent_topic,agent_addr,agent_detail,agent_prompt,has_statistics,agent_status,input_time,update_time,agent_param_tpl,large_model_code
A3: 2 | B3: agent_rule | C3: A 纯下划线 | D3: 业务表 | E3: 21 | F3: 18 | G3: 0 | H3: 0 | I3: rule_name,rule_text,parsed_expression,rule_status,input_time,input_user,update_time,update_user,prompt_key,threshold_config,risk_remark,disposal_advice,additional_analysis,rule_code,additional_analysis_name,rule_struct,fact_analysis,request_params
A4: 3 | B4: app_code_dict | C4: A 纯下划线 | D4: 业务表 | E4: 5 | F4: 3 | G4: 0 | H4: 0 | I4: dict_type,code_value,code_name
A5: 4 | B5: bak_20260916_agent_rule | C5: A 纯下划线 | D5: 备份表 | E5: 2 | F5: 1 | G5: 0 | H5: 0 | I5: request_params | J5: bak 备份表
A6: 5 | B6: bak_20260916_kb_params | C6: A 纯下划线 | D6: 备份表 | E6: 3 | F6: 2 | G6: 0 | H6: 0 | I6: relate_index_set,input_param | J6: bak 备份表
A7: 6 | B7: bak_20260916_relate_input_param | C7: A 纯下划线 | D7: 备份表 | E7: 2 | F7: 1 | G7: 0 | H7: 0 | I7: input_param | J7: bak 备份表
A8: 7 | B8: call_llm_record | C8: A 纯下划线 | D8: 业务表 | E8: 13 | F8: 11 | G8: 0 | H8: 0 | I8: hub_account,trace_id,sort_no,request_time,request_body,response_time,large_model_code,api_key,prompt_tokens,completion_tokens,session_msg_no
A9: 8 | B9: collector_config | C9: A 纯下划线 | D9: 业务表 | E9: 8 | F9: 6 | G9: 0 | H9: 0 | I9: config_name,collector_type,config_json,cron_expression,created_at,updated_at
A10: 9 | B10: collector_config_1 | C10: A 纯下划线 | D10: 业务表 | E10: 8 | F10: 6 | G10: 0 | H10: 0 | I10: config_name,collector_type,config_json,cron_expression,created_at,updated_at
A11: 10 | B11: collector_config_2 | C11: A 纯下划线 | D11: 业务表 | E11: 6 | F11: 4 | G11: 0 | H11: 0 | I11: config_name,collector_type,config_json,cron_expression
A12: 11 | B12: credit_record | C12: A 纯下划线 | D12: 业务表 | E12: 12 | F12: 10 | G12: 0 | H12: 0 | I12: customer_id,contract_no,loan_type,loan_amount,loan_balance,start_date,end_date,loan_purpose,guarantee_type,created_at
A13: 12 | B13: ext_intf_manage | C13: A 纯下划线 | D13: 业务表 | E13: 23 | F13: 22 | G13: 0 | H13: 0 | I13: supplier_id,intf_no,intf_name,intf_path,intf_type_name,intf_request_type,intf_time_out,intf_status,intf_desc,refer_intf_no,refer_intf_status,async_save,battle_flag,battle_report_content,before_handler,input_user_id,input_user_name,input_time,update_user_id,update_user_name,update_time,intf_structure
A14: 13 | B14: ext_intf_param_define | C14: A 纯下划线 | D14: 业务表 | E14: 13 | F14: 12 | G14: 0 | H14: 0 | I14: supplier_id,param_code,param_type,param_value,input_user_id,input_user_name,input_time,update_user_id,update_user_name,update_time,param_position,param_is_required
A15: 14 | B15: ext_intf_param_manage | C15: A 纯下划线 | D15: 业务表 | E15: 25 | F15: 24 | G15: 0 | H15: 0 | I15: supplier_id,intf_no,param_code,param_name,param_type,param_is_required,param_position,param_source,param_value,input_user_id,input_user_name,input_time,update_user_id,update_user_name,update_time,source_type_detail,source_param_code,source_param_type,child_param_code,child_param_name,child_param_type,source_field_dict_id,source_field,source_field_name
A16: 15 | B16: ext_intf_supplier_manage | C16: A 纯下划线 | D16: 业务表 | E16: 11 | F16: 10 | G16: 0 | H16: 0 | I16: supplier_id,supplier_name,intf_type,intf_path,input_user_id,input_user_name,input_time,update_user_id,update_user_name,update_time
A17: 16 | B17: index_relate_index_info | C17: A 纯下划线 | D17: 业务表 | E17: 8 | F17: 7 | G17: 0 | H17: 0 | I17: param_no,relate_param_no,relate_param_id,relate_param_name,relate_group_id,create_time,update_time
A18: 17 | B18: index_relate_info | C18: A 纯下划线 | D18: 业务表 | E18: 5 | F18: 3 | G18: 0 | H18: 0 | I18: index_id,relate_index_id,relate_time
A19: 18 | B19: index_relate_knowledge_info | C19: A 纯下划线 | D19: 业务表 | E19: 9 | F19: 8 | G19: 0 | H19: 0 | I19: param_no,relate_knowledge_no,relate_knowledge_code,relate_knowledge_name,relate_group_id,relate_items,create_time,update_time
... A56: 55 | B56: app_shareholder_info | C56: B 混用 | D56: 业务表 | E56: 13 | F56: 6 | G56: 3 | H56: 0 | I56: stock_num,stock_percent,is_quoted,is_state_owned,is_fake_state_owned,is_listed_company
A57: 56 | B57: bak_20260922_app_ic_shareholder_info | C57: B 混用 | D57: 备份表 | E57: 13 | F57: 1 | G57: 9 | H57: 0 | I57: snapshot_type | J57: bak 备份表
A58: 57 | B58: bak_20260922_app_shareholder_info | C58: B 混用 | D58: 备份表 | E58: 13 | F58: 6 | G58: 3 | H58: 0 | I58: stock_num,stock_percent,is_quoted,is_state_owned,is_fake_state_owned,is_listed_company | J58: bak 备份表
A59: 58 | B59: bak_20260922_dfs_crdt_loan_cust_rel | C59: B 混用 | D59: 备份表 | E59: 42 | F59: 34 | G59: 3 | H59: 0 | I59: cr_cust_num,cust_nm,stat_cur,tax_sale_amt_tot,tax_sale_amt_ch,tax_sale_amt_tb,mon_sale_amt,fin_rpt_dt,fin_rpt_clber,rcvb_fnd_on_acct,oprt_incm,due_fnd_on_acct,acct_zhxx,fzn_amt,dep_y_avg_bal,yr_pty_income,yr_pty_income_ch,yr_pty_income_regy,elec_income,elec_income_ch,elec_income_regy,cr_acr_amt_1,cr_acr_amt_2,dbt_cntpr_and_acr_amt,cr_cntpr_and_acr_amt,hnym_tfrd_amt_dbt_pcnt,hnym_tfrd_amt_cr_pcnt,instd_sal_moly,instd_sal_person_moly,instd_sal_amt_moly,instd_sal_person_moly_hb,instd_sal_amt_moly_hb,instd_sal_person_moly_tb,instd_sal_amt_moly_tb | J59: bak 备份表
A60: 59 | B60: bak_20260922_dfs_final_crdt_loan_cust_rel | C60: B 混用 | D60: 备份表 | E60: 16 | F60: 7 | G60: 5 | H60: 0 | I60: cr_cust_num,cust_nm,rsk_ev,spf_intra,business_time,prmpt_ltr,ev_tp | J60: bak 备份表
A61: 60 | B61: bak_20260922_gfzx_balance_sheet_item | C61: B 混用 | D61: 备份表 | E61: 11 | F61: 5 | G61: 3 | H61: 0 | I61: c_cn_name,c_before_last_qmye,c_last_qmye,c_last_time_qmye,c_current_qmye | J61: bak 备份表
A62: 61 | B62: bak_20260922_gfzx_finance_index_item | C62: B 混用 | D62: 备份表 | E62: 11 | F62: 5 | G62: 3 | H62: 0 | I62: o_cn_name,o_before_last_index,o_last_index,o_last_time_index,o_current_index | J62: bak 备份表
A63: 62 | B63: bak_20260922_gfzx_national_dev | C63: B 混用 | D63: 备份表 | E63: 17 | F63: 12 | G63: 3 | H63: 0 | I63: c_beforeyear,c_lastyear,c_correspondingperiodlastyear,c_sameperiodthisyear,n_beforeyear,n_lastyear,n_correspondingperiodlastyear,n_sameperiodthisyear,o_beforeyear,o_lastyear,o_correspondingperiodlastyear,o_sameperiodthisyear | J63: bak 备份表
A64: 63 | B64: bak_20260922_gfzx_profit_sheet_item | C64: B 混用 | D64: 备份表 | E64: 11 | F64: 5 | G64: 3 | H64: 0 | I64: n_cn_name,n_before_last_qmye,n_last_qmye,n_last_time_qmye,n_current_qmye | J64: bak 备份表
A65: 64 | B65: bak_20260922_std_ecis_t_mining_tags_dd | C65: B 混用 | D65: 备份表 | E65: 9 | F65: 4 | G65: 3 | H65: 0 | I65: cr_cust_num,entp_first_nm,tag_id,tag_name | J65: bak 备份表
A66: 65 | B66: bak_20260922_ws_base_info | C66: B 混用 | D66: 备份表 | E66: 32 | F66: 20 | G66: 3 | H66: 0 | I66: actual_capi,org_no,term_end,credit_no,start_date,district_code,quoted_type,regist_capi,reg_no,belong_org,oper_name,econ_kind_code,end_date,econ_kind,new_status,is_quoted,term_start,collegues_num,is_history,check_date | J66: bak 备份表
A67: 66 | B67: bak_20260922_ws_beneficial_owner | C67: B 混用 | D67: 备份表 | E67: 12 | F67: 1 | G67: 5 | H67: 0 | I67: law_desc | J67: bak 备份表
A68: 67 | B68: bak_20260922_ws_best_shareholding | C68: B 混用 | D68: 备份表 | E68: 17 | F68: 8 | G68: 3 | H68: 0 | I68: sh_type,credit_no,subscribed_amount,stock_num,real_capi,con_date,currency_code,real_capi_date | J68: bak 备份表
... A74: 73 | B74: bak_20260922y_ws_equity_change | C74: B 混用 | D74: 备份表 | E74: 11 | F74: 4 | G74: 3 | H74: 0 | I74: before_percent,change_date,after_percent,public_date | J74: bak 备份表
A75: 74 | B75: customer | C75: B 混用 | D75: 业务表 | E75: 22 | F75: 18 | G75: 1 | H75: 0 | I75: company_name,credit_code,legal_person,actual_controller,registered_capital,paid_capital,establish_date,biz_scope,register_address,holding_type,group_name,customer_type,first_loan_date,last_approval_date,main_bank,settlement_bank,created_at,updated_at
A76: 75 | B76: dfs_crdt_loan_cust_rel | C76: B 混用 | D76: 业务表 | E76: 42 | F76: 34 | G76: 3 | H76: 0 | I76: cr_cust_num,cust_nm,stat_cur,tax_sale_amt_tot,tax_sale_amt_ch,tax_sale_amt_tb,mon_sale_amt,fin_rpt_dt,fin_rpt_clber,rcvb_fnd_on_acct,oprt_incm,due_fnd_on_acct,acct_zhxx,fzn_amt,dep_y_avg_bal,yr_pty_income,yr_pty_income_ch,yr_pty_income_regy,elec_income,elec_income_ch,elec_income_regy,cr_acr_amt_1,cr_acr_amt_2,dbt_cntpr_and_acr_amt,cr_cntpr_and_acr_amt,hnym_tfrd_amt_dbt_pcnt,hnym_tfrd_amt_cr_pcnt,instd_sal_moly,instd_sal_person_moly,instd_sal_amt_moly,instd_sal_person_moly_hb,instd_sal_amt_moly_hb,instd_sal_person_moly_tb,instd_sal_amt_moly_tb
A77: 76 | B77: dfs_final_crdt_loan_cust_rel | C77: B 混用 | D77: 业务表 | E77: 16 | F77: 7 | G77: 5 | H77: 0 | I77: cr_cust_num,cust_nm,rsk_ev,spf_intra,business_time,prmpt_ltr,ev_tp
A78: 77 | B78: gfzx_balance_sheet_item | C78: B 混用 | D78: 业务表 | E78: 11 | F78: 5 | G78: 3 | H78: 0 | I78: c_cn_name,c_before_last_qmye,c_last_qmye,c_last_time_qmye,c_current_qmye
A79: 78 | B79: gfzx_finance_index_item | C79: B 混用 | D79: 业务表 | E79: 11 | F79: 5 | G79: 3 | H79: 0 | I79: o_cn_name,o_before_last_index,o_last_index,o_last_time_index,o_current_index
A80: 79 | B80: gfzx_national_dev | C80: B 混用 | D80: 业务表 | E80: 17 | F80: 12 | G80: 3 | H80: 0 | I80: c_beforeyear,c_lastyear,c_correspondingperiodlastyear,c_sameperiodthisyear,n_beforeyear,n_lastyear,n_correspondingperiodlastyear,n_sameperiodthisyear,o_beforeyear,o_lastyear,o_correspondingperiodlastyear,o_sameperiodthisyear
A81: 80 | B81: gfzx_profit_sheet_item | C81: B 混用 | D81: 业务表 | E81: 11 | F81: 5 | G81: 3 | H81: 0 | I81: n_cn_name,n_before_last_qmye,n_last_qmye,n_last_time_qmye,n_current_qmye
...
